2025-07-07 01:07:16,693 - aiogram.event - ERROR - Cause exception while process update id=359547532 by bot id=7940686992
KeyError: 'max_hp'
Traceback (most recent call last):
  File "C:\Users\Шынгыс\AppData\Local\Programs\Python\Python312\Lib\site-packages\aiogram\dispatcher\dispatcher.py", line 309, in _process_update        
    response = await self.feed_update(bot, update, **kwargs)
               ^^^^^^^^^^^^^^^^^^^^^^^^^^^^^^^^^^^^^^^^^^^^^
  File "C:\Users\Шынгыс\AppData\Local\Programs\Python\Python312\Lib\site-packages\aiogram\dispatcher\dispatcher.py", line 158, in feed_update
    response = await self.update.wrap_outer_middleware(
               ^^^^^^^^^^^^^^^^^^^^^^^^^^^^^^^^^^^^^^^^
  File "C:\Users\Шынгыс\AppData\Local\Programs\Python\Python312\Lib\site-packages\aiogram\dispatcher\middlewares\error.py", line 25, in __call__
    return await handler(event, data)
           ^^^^^^^^^^^^^^^^^^^^^^^^^^
  File "C:\Users\Шынгыс\AppData\Local\Programs\Python\Python312\Lib\site-packages\aiogram\dispatcher\middlewares\user_context.py", line 49, in __call__  
    return await handler(event, data)
           ^^^^^^^^^^^^^^^^^^^^^^^^^^
  File "C:\Users\Шынгыс\AppData\Local\Programs\Python\Python312\Lib\site-packages\aiogram\fsm\middleware.py", line 42, in __call__
    return await handler(event, data)
           ^^^^^^^^^^^^^^^^^^^^^^^^^^
  File "C:\Users\Шынгыс\AppData\Local\Programs\Python\Python312\Lib\site-packages\aiogram\dispatcher\event\telegram.py", line 121, in trigger
    return await wrapped_inner(event, kwargs)
           ^^^^^^^^^^^^^^^^^^^^^^^^^^^^^^^^^^
  File "C:\Users\Шынгыс\AppData\Local\Programs\Python\Python312\Lib\site-packages\aiogram\dispatcher\event\handler.py", line 43, in call
    return await wrapped()
           ^^^^^^^^^^^^^^^
  File "C:\Users\Шынгыс\AppData\Local\Programs\Python\Python312\Lib\site-packages\aiogram\dispatcher\dispatcher.py", line 276, in _listen_update
    return await self.propagate_event(update_type=update_type, event=event, **kwargs)
           ^^^^^^^^^^^^^^^^^^^^^^^^^^^^^^^^^^^^^^^^^^^^^^^^^^^^^^^^^^^^^^^^^^^^^^^^^^
  File "C:\Users\Шынгыс\AppData\Local\Programs\Python\Python312\Lib\site-packages\aiogram\dispatcher\router.py", line 142, in propagate_event
    return await observer.wrap_outer_middleware(_wrapped, event=event, data=kwargs)
           ^^^^^^^^^^^^^^^^^^^^^^^^^^^^^^^^^^^^^^^^^^^^^^^^^^^^^^^^^^^^^^^^^^^^^^^^
  File "C:\Users\Шынгыс\AppData\Local\Programs\Python\Python312\Lib\site-packages\aiogram\dispatcher\router.py", line 137, in _wrapped
    return await self._propagate_event(
           ^^^^^^^^^^^^^^^^^^^^^^^^^^^^
  File "C:\Users\Шынгыс\AppData\Local\Programs\Python\Python312\Lib\site-packages\aiogram\dispatcher\router.py", line 170, in _propagate_event
    response = await router.propagate_event(update_type=update_type, event=event, **kwargs)
               ^^^^^^^^^^^^^^^^^^^^^^^^^^^^^^^^^^^^^^^^^^^^^^^^^^^^^^^^^^^^^^^^^^^^^^^^^^^^
  File "C:\Users\Шынгыс\AppData\Local\Programs\Python\Python312\Lib\site-packages\aiogram\dispatcher\router.py", line 142, in propagate_event
    return await observer.wrap_outer_middleware(_wrapped, event=event, data=kwargs)
           ^^^^^^^^^^^^^^^^^^^^^^^^^^^^^^^^^^^^^^^^^^^^^^^^^^^^^^^^^^^^^^^^^^^^^^^^
  File "C:\Users\Шынгыс\AppData\Local\Programs\Python\Python312\Lib\site-packages\aiogram\dispatcher\router.py", line 137, in _wrapped
    return await self._propagate_event(
           ^^^^^^^^^^^^^^^^^^^^^^^^^^^^
  File "C:\Users\Шынгыс\AppData\Local\Programs\Python\Python312\Lib\site-packages\aiogram\dispatcher\router.py", line 162, in _propagate_event
    response = await observer.trigger(event, **kwargs)
               ^^^^^^^^^^^^^^^^^^^^^^^^^^^^^^^^^^^^^^^
  File "C:\Users\Шынгыс\AppData\Local\Programs\Python\Python312\Lib\site-packages\aiogram\dispatcher\event\telegram.py", line 121, in trigger
    return await wrapped_inner(event, kwargs)
           ^^^^^^^^^^^^^^^^^^^^^^^^^^^^^^^^^^
  File "C:\Users\Шынгыс\AppData\Local\Programs\Python\Python312\Lib\site-packages\aiogram\dispatcher\event\handler.py", line 43, in call
    return await wrapped()
           ^^^^^^^^^^^^^^^
  File "C:\Users\Шынгыс\character_bot\handlers\main_menu.py", line 63, in process_menu_battle
    await start_combat(callback.message, state, character, enemy_id)
  File "C:\Users\Шынгыс\character_bot\handlers\combat.py", line 55, in start_combat
    "player_max_hp": character_data['stats']['max_hp'],
                     ~~~~~~~~~~~~~~~~~~~~~~~^^^^^^^^^^
KeyError: 'max_hp'